<log>
  <section_ name='My rescued section'>
    <rescued_exception_ class='RuntimeError' message='Boo!'>
      <backtrace_>
        <![CDATA[
example.rb:6:in `block (2 levels) in test_example'
example.rb:5:in `block in test_example'
example.rb:4:in `new'
example.rb:4:in `test_example'
]]>
      </backtrace_>
    </rescued_exception_>
  </section_>
  <comment_>
    This code will be reached, because it is not in the terminated section.
  </comment_>
</log>
