<log>
  <summary verdicts='1' failures='1' errors='2'/>
  <section name='Test' method='verdict_assert_same?' type='error'>
    <section name='Args=[]'>
      <rescued_exception>
        <class>
          ArgumentError
        </class>
        <message>
          wrong number of arguments (given 1, expected 3..4)
        </message>
        <backtrace/>
      </rescued_exception>
    </section>
    <section name='Args=[nil, nil, nil]'>
      <rescued_exception>
        <class>
          ArgumentError
        </class>
        <message>
          wrong number of arguments (given 5, expected 3..4)
        </message>
        <backtrace/>
      </rescued_exception>
    </section>
  </section>
  <verdict method='verdict_assert_equal?' outcome='failed' id='__error_count__'>
    <exp_value>
      0
    </exp_value>
    <act_value>
      2
    </act_value>
    <exception class='Minitest::Assertion'>
      <message>
        Expected: 0 Actual: 2
      </message>
      <backtrace/>
    </exception>
  </verdict>
</log>
