<log>
  <summary verdicts='0' failures='0' errors='2'/>
  <section name='Test' method='verdict_assert_operator?' type='error'>
    <section name='Args=[]'>
      <rescued_exception class='ArgumentError' message='wrong number of arguments (given 1, expected 4..5)'>
        <backtrace/>
      </rescued_exception>
    </section>
    <section name='Args=[nil, nil, nil, nil]'>
      <rescued_exception class='ArgumentError' message='wrong number of arguments (given 6, expected 4..5)'>
        <backtrace/>
      </rescued_exception>
    </section>
  </section>
</log>
