<log>
  <summary_ verdicts='1' failures='1' errors='2'/>
  <section_ name='Test' method='verdict_refute_kind_of?' type='error'>
    <section_ name='Args=[]'>
      <rescued_exception_ class='ArgumentError' message='wrong number of arguments (given 1, expected 3..4)'>
        <backtrace_>
        </backtrace_>
      </rescued_exception_>
    </section_>
    <section_ name='Args=[nil, nil, nil, &quot;Message 1&quot;]'>
      <rescued_exception_ class='ArgumentError' message='wrong number of arguments (given 5, expected 3..4)'>
        <backtrace_>
        </backtrace_>
      </rescued_exception_>
    </section_>
  </section_>
  <verdict_ method='verdict_assert_equal?' outcome='failed' id='error_count'>
    <expected_ class='Integer' value='0'/>
    <actual_ class='Integer' value='2'/>
    <exception_ class='Minitest::Assertion' message='Expected: 0'>
      <backtrace_/>
    </exception_>
  </verdict_>
</log>
