<log>
  <summary_ verdicts='0' failures='0' errors='2'/>
  <section_ name='Test' method='verdict_refute_operator?' type='error'>
    <section_ name='Args=[]'>
      <rescued_exception_ class='ArgumentError' message='wrong number of arguments (given 1, expected 4..5)'>
        <backtrace_/>
      </rescued_exception_>
    </section_>
    <section_ name='Args=[nil, nil, nil, nil]'>
      <rescued_exception_ class='ArgumentError' message='wrong number of arguments (given 6, expected 4..5)'>
        <backtrace_/>
      </rescued_exception_>
    </section_>
  </section_>
</log>
